Workbook

Sheet Hourly Bike-Ped Counts
B2: 700 S @ 1700 W - Intersection Count
B3: Date: 11.05.25
B4: Weather: Partly Cloudy/Cloudy - 70 H 49 L
F6: From | X6: To
F7: Road | J7: Bike Lane | N7: Bikeway | P7: Sidewalk | X7: Road | AB7: Bike Lane | AF7: Bikeway | AH7: Sidewalk | AP7: Car No Yield | AQ7: Car Yield | AR7: CG Car No Yield | AS7: CG Car Yield | AT7: Bike No Yield | AU7: Car in Bikeway | AV7: Ped Out of Crosswalk | AW7: Cargo Bike | AX7: Bike Passenger | AY7: Stroller | AZ7: Jogger | BA7: Dog | BB7: Backpack | BC7: Panniers | BD7: Bike Trailer
B8: 0 | C8: Totals | F8: W | G8: N | H8: E | I8: S | J8: N-W | K8: N-E | L8: S-E | M8: S-W | N8: W | O8: E | P8: W-S | Q8: W-N | R8: N-W | S8: N-E | T8: E-N | U8: E-S | V8: S-E | W8: S-W | X8: W | Y8: N | Z8: E | AA8: S | AB8: N-W | AC8: N-E | AD8: S-E | AE8: S-W | AF8: W | AG8: E | AH8: W-S | AI8: W-N | AJ8: N-W | AK8: N-E | AL8: E-N | AM8: E-S | AN8: S-E | AO8: S-W
B9: Pedestrian | C9: =SUM(F9:W9) -> 0 | E9: Pedestrian
B10: Bike | C10: =SUM(F10:W10) -> 0 | E10: Bike
B11: Scooter | C11: =SUM(F11:W11) -> 0 | E11: Scooter
B12: Other | C12: =SUM(F12:W12) -> 0 | E12: Other
C13: =SUM(C9:C12) -> 0
F15: From | X15: To
F16: Road | J16: Bike Lane | N16: Bikeway | P16: Sidewalk | X16: Road | AB16: Bike Lane | AF16: Bikeway | AH16: Sidewalk | AP16: Car No Yield | AQ16: Car Yield | AR16: CG Car No Yield | AS16: CG Car Yield | AT16: Bike No Yield | AU16: Car in Bikeway | AV16: Ped Out of Crosswalk | AW16: Cargo Bike | AX16: Bike Passenger | AY16: Stroller | AZ16: Jogger | BA16: Dog | BB16: Backpack | BC16: Panniers | BD16: Bike Trailer
B17: 0.010416667 | C17: Totals | F17: W | G17: N | H17: E | I17: S | J17: N-W | K17: N-E | L17: S-E | M17: S-W | N17: W | O17: E | P17: W-S | Q17: W-N | R17: N-W | S17: N-E | T17: E-N | U17: E-S | V17: S-E | W17: S-W | X17: W | Y17: N | Z17: E | AA17: S | AB17: N-W | AC17: N-E | AD17: S-E | AE17: S-W | AF17: W | AG17: E | AH17: W-S | AI17: W-N | AJ17: N-W | AK17: N-E | AL17: E-N | AM17: E-S | AN17: S-E | AO17: S-W
B18: Pedestrian | C18: =SUM(F18:W18) -> 0 | E18: Pedestrian
B19: Bike | C19: =SUM(F19:W19) -> 0 | E19: Bike
B20: Scooter | C20: =SUM(F20:W20) -> 0 | E20: Scooter
B21: Other | C21: =SUM(F21:W21) -> 0 | E21: Other
C22: =SUM(C18:C21) -> 0
F24: From | X24: To
F25: Road | J25: Bike Lane | N25: Bikeway | P25: Sidewalk | X25: Road | AB25: Bike Lane | AF25: Bikeway | AH25: Sidewalk | AP25: Car No Yield | AQ25: Car Yield | AR25: CG Car No Yield | AS25: CG Car Yield | AT25: Bike No Yield | AU25: Car in Bikeway | AV25: Ped Out of Crosswalk | AW25: Cargo Bike | AX25: Bike Passenger | AY25: Stroller | AZ25: Jogger | BA25: Dog | BB25: Backpack | BC25: Panniers | BD25: Bike Trailer
B26: 0.020833333 | C26: Totals | F26: W | G26: N | H26: E | I26: S | J26: N-W | K26: N-E | L26: S-E | M26: S-W | N26: W | O26: E | P26: W-S | Q26: W-N | R26: N-W | S26: N-E | T26: E-N | U26: E-S | V26: S-E | W26: S-W | X26: W | Y26: N | Z26: E | AA26: S | AB26: N-W | AC26: N-E | AD26: S-E | AE26: S-W | AF26: W | AG26: E | AH26: W-S | AI26: W-N | AJ26: N-W | AK26: N-E | AL26: E-N | AM26: E-S | AN26: S-E | AO26: S-W
B27: Pedestrian | C27: =SUM(F27:W27) -> 0 | E27: Pedestrian
B28: Bike | C28: =SUM(F28:W28) -> 0 | E28: Bike
B29: Scooter | C29: =SUM(F29:W29) -> 0 | E29: Scooter
B30: Other | C30: =SUM(F30:W30) -> 0 | E30: Other
C31: =SUM(C27:C30) -> 0
F33: From | X33: To
F34: Road | J34: Bike Lane | N34: Bikeway | P34: Sidewalk | X34: Road | AB34: Bike Lane | AF34: Bikeway | AH34: Sidewalk | AP34: Car No Yield | AQ34: Car Yield | AR34: CG Car No Yield | AS34: CG Car Yield | AT34: Bike No Yield | AU34: Car in Bikeway | AV34: Ped Out of Crosswalk | AW34: Cargo Bike | AX34: Bike Passenger | AY34: Stroller | AZ34: Jogger | BA34: Dog | BB34: Backpack | BC34: Panniers | BD34: Bike Trailer
B35: 0.03125 | C35: Totals | F35: W | G35: N | H35: E | I35: S | J35: N-W | K35: N-E | L35: S-E | M35: S-W | N35: W | O35: E | P35: W-S | Q35: W-N | R35: N-W | S35: N-E | T35: E-N | U35: E-S | V35: S-E | W35: S-W | X35: W | Y35: N | Z35: E | AA35: S | AB35: N-W | AC35: N-E | AD35: S-E | AE35: S-W | AF35: W | AG35: E | AH35: W-S | AI35: W-N | AJ35: N-W | AK35: N-E | AL35: E-N | AM35: E-S | AN35: S-E | AO35: S-W
B36: Pedestrian | C36: =SUM(F36:W36) -> 0 | E36: Pedestrian
B37: Bike | C37: =SUM(F37:W37) -> 0 | E37: Bike
B38: Scooter | C38: =SUM(F38:W38) -> 0 | E38: Scooter
B39: Other | C39: =SUM(F39:W39) -> 0 | E39: Other
C40: =SUM(C36:C39) -> 0
F42: From | X42: To
F43: Road | J43: Bike Lane | N43: Bikeway | P43: Sidewalk | X43: Road | AB43: Bike Lane | AF43: Bikeway | AH43: Sidewalk | AP43: Car No Yield | AQ43: Car Yield | AR43: CG Car No Yield | AS43: CG Car Yield | AT43: Bike No Yield | AU43: Car in Bikeway | AV43: Ped Out of Crosswalk | AW43: Cargo Bike | AX43: Bike Passenger | AY43: Stroller | AZ43: Jogger | BA43: Dog | BB43: Backpack | BC43: Panniers | BD43: Bike Trailer
B44: 0.041666667 | C44: Totals | F44: W | G44: N | H44: E | I44: S | J44: N-W | K44: N-E | L44: S-E | M44: S-W | N44: W | O44: E | P44: W-S | Q44: W-N | R44: N-W | S44: N-E | T44: E-N | U44: E-S | V44: S-E | W44: S-W | X44: W | Y44: N | Z44: E | AA44: S | AB44: N-W | AC44: N-E | AD44: S-E | AE44: S-W | AF44: W | AG44: E | AH44: W-S | AI44: W-N | AJ44: N-W | AK44: N-E | AL44: E-N | AM44: E-S | AN44: S-E | AO44: S-W
B45: Pedestrian | C45: =SUM(F45:W45) -> 0 | E45: Pedestrian
B46: Bike | C46: =SUM(F46:W46) -> 0 | E46: Bike
...

Sheet Count Summary
B2: 15-Minute Intervals | I2: 1-Hour Intervals
B3: Time | C3: Pedestrian | D3: Bike | E3: Scooter | F3: Other | G3: 15-min Total | I3: Time | J3: Pedestrian | K3: Bike | L3: Scooter | M3: Other | N3: Hourly Total
B4: 0 | C4: ='Hourly Bike-Ped Counts'!C9 -> 0 | D4: ='Hourly Bike-Ped Counts'!C10 -> 0 | E4: ='Hourly Bike-Ped Counts'!C11 -> 0 | F4: ='Hourly Bike-Ped Counts'!C12 -> 0 | G4: =SUM(C4:F4) -> 0 | I4: 0 | J4: =SUM(C4:C7) -> 0 | K4: =SUM(D4:D7) -> 0 | L4: =SUM(E4:E7) -> 0 | M4: =SUM(F4:F7) -> 0 | N4: =SUM(J4:M4) -> 0
B5: 0.010416667 | C5: ='Hourly Bike-Ped Counts'!C18 -> 0 | D5: ='Hourly Bike-Ped Counts'!C19 -> 0 | E5: ='Hourly Bike-Ped Counts'!C20 -> 0 | F5: ='Hourly Bike-Ped Counts'!C21 -> 0 | G5: =SUM(C5:F5) -> 0 | I5: 0.041666667 | J5: =SUM(C8:C11) -> 0 | K5: =SUM(D8:D11) -> 0 | L5: =SUM(E8:E11) -> 0 | M5: =SUM(F8:F11) -> 0 | N5: =SUM(J5:M5) -> 0
B6: 0.020833333 | C6: ='Hourly Bike-Ped Counts'!C27 -> 0 | D6: ='Hourly Bike-Ped Counts'!C28 -> 0 | E6: ='Hourly Bike-Ped Counts'!C29 -> 0 | F6: ='Hourly Bike-Ped Counts'!C30 -> 0 | G6: =SUM(C6:F6) -> 0 | I6: 0.083333333 | J6: =SUM(C12:C15) -> 0 | K6: =SUM(D12:D15) -> 0 | L6: =SUM(E12:E15) -> 0 | M6: =SUM(F12:F15) -> 0 | N6: =SUM(J6:M6) -> 0
B7: 0.03125 | C7: ='Hourly Bike-Ped Counts'!C36 -> 0 | D7: ='Hourly Bike-Ped Counts'!C37 -> 0 | E7: ='Hourly Bike-Ped Counts'!C38 -> 0 | F7: ='Hourly Bike-Ped Counts'!C40 -> 0 | G7: =SUM(C7:F7) -> 0 | I7: 0.125 | J7: =SUM(C16:C19) -> 0 | K7: =SUM(D16:D19) -> 0 | L7: =SUM(E16:E19) -> 0 | M7: =SUM(F16:F19) -> 0 | N7: =SUM(J7:M7) -> 0
B8: 0.041666667 | C8: ='Hourly Bike-Ped Counts'!C45 -> 0 | D8: ='Hourly Bike-Ped Counts'!C46 -> 0 | E8: ='Hourly Bike-Ped Counts'!C47 -> 0 | F8: ='Hourly Bike-Ped Counts'!C48 -> 0 | G8: =SUM(C8:F8) -> 0 | I8: 0.16666667 | J8: =SUM(C20:C23) -> 0 | K8: =SUM(D20:D23) -> 0 | L8: =SUM(E20:E23) -> 0 | M8: =SUM(F20:F23) -> 0 | N8: =SUM(J8:M8) -> 0
B9: 0.052083333 | C9: ='Hourly Bike-Ped Counts'!C54 -> 0 | D9: ='Hourly Bike-Ped Counts'!C55 -> 0 | E9: ='Hourly Bike-Ped Counts'!C56 -> 0 | F9: ='Hourly Bike-Ped Counts'!C57 -> 0 | G9: =SUM(C9:F9) -> 0 | I9: 0.20833333 | J9: =SUM(C24:C27) -> 7 | K9: =SUM(D24:D27) -> 0 | L9: =SUM(E24:E27) -> 0 | M9: =SUM(F24:F27) -> 0 | N9: =SUM(J9:M9) -> 7
B10: 0.0625 | C10: ='Hourly Bike-Ped Counts'!C563 -> 0 | D10: ='Hourly Bike-Ped Counts'!C64 -> 0 | E10: ='Hourly Bike-Ped Counts'!C65 -> 0 | F10: ='Hourly Bike-Ped Counts'!C66 -> 0 | G10: =SUM(C10:F10) -> 0 | I10: 0.25 | J10: =SUM(C28:C31) -> 17 | K10: =SUM(D28:D31) -> 2 | L10: =SUM(E28:E31) -> 0 | M10: =SUM(F28:F31) -> 0 | N10: =SUM(J10:M10) -> 19
B11: 0.072916667 | C11: ='Hourly Bike-Ped Counts'!C72 -> 0 | D11: ='Hourly Bike-Ped Counts'!C73 -> 0 | E11: ='Hourly Bike-Ped Counts'!C74 -> 0 | F11: ='Hourly Bike-Ped Counts'!C75 -> 0 | G11: =SUM(C11:F11) -> 0 | I11: 0.29166667 | J11: =SUM(C32:C35) -> 12 | K11: =SUM(D32:D35) -> 5 | L11: =SUM(E32:E35) -> 1 | M11: =SUM(F32:F35) -> 0 | N11: =SUM(J11:M11) -> 18
B12: 0.083333333 | C12: ='Hourly Bike-Ped Counts'!C81 -> 0 | D12: ='Hourly Bike-Ped Counts'!C82 -> 0 | E12: ='Hourly Bike-Ped Counts'!C83 -> 0 | F12: ='Hourly Bike-Ped Counts'!C84 -> 0 | G12: =SUM(C12:F12) -> 0 | I12: 0.33333333 | J12: =SUM(C36:C39) -> 27 | K12: =SUM(D36:D39) -> 51 | L12: =SUM(E36:E39) -> 69 | M12: =SUM(F36:F39) -> 0 | N12: =SUM(J12:M12) -> 147
B13: 0.09375 | C13: ='Hourly Bike-Ped Counts'!C90 -> 0 | D13: ='Hourly Bike-Ped Counts'!C91 -> 0 | E13: ='Hourly Bike-Ped Counts'!C92 -> 0 | F13: ='Hourly Bike-Ped Counts'!C93 -> 0 | G13: =SUM(C13:F13) -> 0 | I13: 0.375 | J13: =SUM(C40:C43) -> 42 | K13: =SUM(D40:D43) -> 25 | L13: =SUM(E40:E43) -> 18 | M13: =SUM(F40:F43) -> 0 | N13: =SUM(J13:M13) -> 85
B14: 0.10416667 | C14: ='Hourly Bike-Ped Counts'!C99 -> 0 | D14: ='Hourly Bike-Ped Counts'!C100 -> 0 | E14: ='Hourly Bike-Ped Counts'!C101 -> 0 | F14: ='Hourly Bike-Ped Counts'!C102 -> 0 | G14: =SUM(C14:F14) -> 0 | I14: 0.41666667 | J14: =SUM(C44:C47) -> 6 | K14: =SUM(D44:D47) -> 2 | L14: =SUM(E44:E47) -> 0 | M14: =SUM(F44:F47) -> 0 | N14: =SUM(J14:M14) -> 8
B15: 0.11458333 | C15: ='Hourly Bike-Ped Counts'!C108 -> 0 | D15: ='Hourly Bike-Ped Counts'!C109 -> 0 | E15: ='Hourly Bike-Ped Counts'!C110 -> 0 | F15: ='Hourly Bike-Ped Counts'!C111 -> 0 | G15: =SUM(C15:F15) -> 0 | I15: 0.45833333 | J15: =SUM(C48:C51) -> 5 | K15: =SUM(D48:D51) -> 2 | L15: =SUM(E48:E51) -> 0 | M15: =SUM(F48:F51) -> 0 | N15: =SUM(J15:M15) -> 7
B16: 0.125 | C16: ='Hourly Bike-Ped Counts'!C117 -> 0 | D16: ='Hourly Bike-Ped Counts'!C118 -> 0 | E16: ='Hourly Bike-Ped Counts'!C119 -> 0 | F16: ='Hourly Bike-Ped Counts'!C120 -> 0 | G16: =SUM(C16:F16) -> 0 | I16: 0.5 | J16: =SUM(C52:C55) -> 12 | K16: =SUM(D52:D55) -> 5 | L16: =SUM(E52:E55) -> 0 | M16: =SUM(F52:F55) -> 0 | N16: =SUM(J16:M16) -> 17
B17: 0.13541667 | C17: ='Hourly Bike-Ped Counts'!C126 -> 0 | D17: ='Hourly Bike-Ped Counts'!C127 -> 0 | E17: ='Hourly Bike-Ped Counts'!C128 -> 0 | F17: ='Hourly Bike-Ped Counts'!C129 -> 0 | G17: =SUM(C17:F17) -> 0 | I17: 0.54166667 | J17: =SUM(C56:C59) -> 6 | K17: =SUM(D56:D59) -> 2 | L17: =SUM(E56:E59) -> 1 | M17: =SUM(F56:F59) -> 0 | N17: =SUM(J17:M17) -> 9
B18: 0.14583333 | C18: ='Hourly Bike-Ped Counts'!C135 -> 0 | D18: ='Hourly Bike-Ped Counts'!C136 -> 0 | E18: ='Hourly Bike-Ped Counts'!C137 -> 0 | F18: ='Hourly Bike-Ped Counts'!C138 -> 0 | G18: =SUM(C18:F18) -> 0 | I18: 0.58333333 | J18: =SUM(C60:C63) -> 6 | K18: =SUM(D60:D63) -> 8 | L18: =SUM(E60:E63) -> 1 | M18: =SUM(F60:F63) -> 0 | N18: =SUM(J18:M18) -> 15
B19: 0.15625 | C19: ='Hourly Bike-Ped Counts'!C144 -> 0 | D19: ='Hourly Bike-Ped Counts'!C145 -> 0 | E19: ='Hourly Bike-Ped Counts'!C146 -> 0 | F19: ='Hourly Bike-Ped Counts'!C147 -> 0 | G19: =SUM(C19:F19) -> 0 | I19: 0.625 | J19: =SUM(C64:C67) -> 95 | K19: =SUM(D64:D67) -> 78 | L19: =SUM(E64:E67) -> 64 | M19: =SUM(F64:F67) -> 1 | N19: =SUM(J19:M19) -> 238
B20: 0.16666667 | C20: ='Hourly Bike-Ped Counts'!C153 -> 0 | D20: ='Hourly Bike-Ped Counts'!C154 -> 0 | E20: ='Hourly Bike-Ped Counts'!C155 -> 0 | F20: ='Hourly Bike-Ped Counts'!C156 -> 0 | G20: =SUM(C20:F20) -> 0 | I20: 0.66666667 | J20: =SUM(C68:C71) -> 15 | K20: =SUM(D68:D71) -> 2 | L20: =SUM(E68:E71) -> 1 | M20: =SUM(F68:F71) -> 0 | N20: =SUM(J20:M20) -> 18
B21: 0.17708333 | C21: ='Hourly Bike-Ped Counts'!C162 -> 0 | D21: ='Hourly Bike-Ped Counts'!C163 -> 0 | E21: ='Hourly Bike-Ped Counts'!C164 -> 0 | F21: ='Hourly Bike-Ped Counts'!C165 -> 0 | G21: =SUM(C21:F21) -> 0 | I21: 0.70833333 | J21: =SUM(C72:C75) -> 14 | K21: =SUM(D72:D75) -> 5 | L21: =SUM(E72:E75) -> 0 | M21: =SUM(F72:F75) -> 0 | N21: =SUM(J21:M21) -> 19
B22: 0.1875 | C22: ='Hourly Bike-Ped Counts'!C171 -> 0 | D22: ='Hourly Bike-Ped Counts'!C172 -> 0 | E22: ='Hourly Bike-Ped Counts'!C173 -> 0 | F22: ='Hourly Bike-Ped Counts'!C174 -> 0 | G22: =SUM(C22:F22) -> 0 | I22: 0.75 | J22: =SUM(C76:C79) -> 8 | K22: =SUM(D76:D79) -> 2 | L22: =SUM(E76:E79) -> 0 | M22: =SUM(F76:F79) -> 0 | N22: =SUM(J22:M22) -> 10
B23: 0.19791667 | C23: ='Hourly Bike-Ped Counts'!C180 -> 0 | D23: ='Hourly Bike-Ped Counts'!C181 -> 0 | E23: ='Hourly Bike-Ped Counts'!C182 -> 0 | F23: ='Hourly Bike-Ped Counts'!C183 -> 0 | G23: =SUM(C23:F23) -> 0 | I23: 0.79166667 | J23: =SUM(C80:C83) -> 3 | K23: =SUM(D80:D83) -> 0 | L23: =SUM(E80:E83) -> 0 | M23: =SUM(F80:F83) -> 0 | N23: =SUM(J23:M23) -> 3
B24: 0.20833333 | C24: ='Hourly Bike-Ped Counts'!C189 -> 0 | D24: ='Hourly Bike-Ped Counts'!C190 -> 0 | E24: ='Hourly Bike-Ped Counts'!C191 -> 0 | F24: ='Hourly Bike-Ped Counts'!C192 -> 0 | G24: =SUM(C24:F24) -> 0 | I24: 0.83333333 | J24: =SUM(C84:C87) -> 0 | K24: =SUM(D84:D87) -> 1 | L24: =SUM(E84:E87) -> 0 | M24: =SUM(F84:F87) -> 0 | N24: =SUM(J24:M24) -> 1
B25: 0.21875 | C25: ='Hourly Bike-Ped Counts'!C198 -> 1 | D25: ='Hourly Bike-Ped Counts'!C199 -> 0 | E25: ='Hourly Bike-Ped Counts'!C200 -> 0 | F25: ='Hourly Bike-Ped Counts'!C201 -> 0 | G25: =SUM(C25:F25) -> 1 | I25: 0.875 | J25: =SUM(C88:C91) -> 2 | K25: =SUM(D88:D91) -> 0 | L25: =SUM(E88:E91) -> 0 | M25: =SUM(F88:F91) -> 0 | N25: =SUM(J25:M25) -> 2
B26: 0.22916667 | C26: ='Hourly Bike-Ped Counts'!C207 -> 2 | D26: ='Hourly Bike-Ped Counts'!C208 -> 0 | E26: ='Hourly Bike-Ped Counts'!C209 -> 0 | F26: ='Hourly Bike-Ped Counts'!C210 -> 0 | G26: =SUM(C26:F26) -> 2 | I26: 0.91666667 | J26: =SUM(C92:C95) -> 0 | K26: =SUM(D92:D95) -> 0 | L26: =SUM(E92:E95) -> 2 | M26: =SUM(F92:F95) -> 0 | N26: =SUM(J26:M26) -> 2
B27: 0.23958333 | C27: ='Hourly Bike-Ped Counts'!C216 -> 4 | D27: ='Hourly Bike-Ped Counts'!C217 -> 0 | E27: ='Hourly Bike-Ped Counts'!C218 -> 0 | F27: ='Hourly Bike-Ped Counts'!C219 -> 0 | G27: =SUM(C27:F27) -> 4 | I27: 0.95833333 | J27: =SUM(C96:C99) -> 2 | K27: =SUM(D96:D99) -> 0 | L27: =SUM(E96:E99) -> 0 | M27: =SUM(F96:F99) -> 0 | N27: =SUM(J27:M27) -> 2
B28: 0.25 | C28: ='Hourly Bike-Ped Counts'!C225 -> 1 | D28: ='Hourly Bike-Ped Counts'!C226 -> 0 | E28: ='Hourly Bike-Ped Counts'!C227 -> 0 | F28: ='Hourly Bike-Ped Counts'!C228 -> 0 | G28: =SUM(C28:F28) -> 1 | I28: Total | J28: =SUM(J4:J27) -> 279 | K28: =SUM(K4:K27) -> 190 | L28: =SUM(L4:L27) -> 157 | M28: =SUM(M4:M27) -> 1 | N28: =SUM(N4:N27) -> 627
B29: 0.26041667 | C29: ='Hourly Bike-Ped Counts'!C234 -> 6 | D29: ='Hourly Bike-Ped Counts'!C235 -> 0 | E29: ='Hourly Bike-Ped Counts'!C236 -> 0 | F29: ='Hourly Bike-Ped Counts'!C237 -> 0 | G29: =SUM(C29:F29) -> 6
B30: 0.27083333 | C30: ='Hourly Bike-Ped Counts'!C243 -> 6 | D30: ='Hourly Bike-Ped Counts'!C244 -> 2 | E30: ='Hourly Bike-Ped Counts'!C245 -> 0 | F30: ='Hourly Bike-Ped Counts'!C246 -> 0 | G30: =SUM(C30:F30) -> 8
B31: 0.28125 | C31: ='Hourly Bike-Ped Counts'!C252 -> 4 | D31: ='Hourly Bike-Ped Counts'!C253 -> 0 | E31: ='Hourly Bike-Ped Counts'!C254 -> 0 | F31: ='Hourly Bike-Ped Counts'!C255 -> 0 | G31: =SUM(C31:F31) -> 4
B32: 0.29166667 | C32: ='Hourly Bike-Ped Counts'!C261 -> 5 | D32: ='Hourly Bike-Ped Counts'!C262 -> 0 | E32: ='Hourly Bike-Ped Counts'!C263 -> 1 | F32: ='Hourly Bike-Ped Counts'!C264 -> 0 | G32: =SUM(C32:F32) -> 6
B33: 0.30208333 | C33: ='Hourly Bike-Ped Counts'!C270 -> 5 | D33: ='Hourly Bike-Ped Counts'!C271 -> 4 | E33: ='Hourly Bike-Ped Counts'!C272 -> 0 | F33: ='Hourly Bike-Ped Counts'!C273 -> 0 | G33: =SUM(C33:F33) -> 9
B34: 0.3125 | C34: ='Hourly Bike-Ped Counts'!C279 -> 1 | D34: ='Hourly Bike-Ped Counts'!C280 -> 1 | E34: ='Hourly Bike-Ped Counts'!C281 -> 0 | F34: ='Hourly Bike-Ped Counts'!C282 -> 0 | G34: =SUM(C34:F34) -> 2
B35: 0.32291667 | C35: ='Hourly Bike-Ped Counts'!C288 -> 1 | D35: ='Hourly Bike-Ped Counts'!C289 -> 0 | E35: ='Hourly Bike-Ped Counts'!C290 -> 0 | F35: ='Hourly Bike-Ped Counts'!C291 -> 0 | G35: =SUM(C35:F35) -> 1
B36: 0.33333333 | C36: ='Hourly Bike-Ped Counts'!C297 -> 1 | D36: ='Hourly Bike-Ped Counts'!C298 -> 1 | E36: ='Hourly Bike-Ped Counts'!C299 -> 0 | F36: ='Hourly Bike-Ped Counts'!C300 -> 0 | G36: =SUM(C36:F36) -> 2
B37: 0.34375 | C37: ='Hourly Bike-Ped Counts'!C306 -> 5 | D37: ='Hourly Bike-Ped Counts'!C307 -> 2 | E37: ='Hourly Bike-Ped Counts'!C308 -> 0 | F37: ='Hourly Bike-Ped Counts'!C309 -> 0 | G37: =SUM(C37:F37) -> 7
B38: 0.35416667 | C38: ='Hourly Bike-Ped Counts'!C315 -> 3 | D38: ='Hourly Bike-Ped Counts'!C316 -> 7 | E38: ='Hourly Bike-Ped Counts'!C317 -> 6 | F38: ='Hourly Bike-Ped Counts'!C318 -> 0 | G38: =SUM(C38:F38) -> 16
B39: 0.36458333 | C39: ='Hourly Bike-Ped Counts'!C324 -> 18 | D39: ='Hourly Bike-Ped Counts'!C325 -> 41 | E39: ='Hourly Bike-Ped Counts'!C326 -> 63 | F39: ='Hourly Bike-Ped Counts'!C327 -> 0 | G39: =SUM(C39:F39) -> 122
B40: 0.375 | C40: ='Hourly Bike-Ped Counts'!C333 -> 28 | D40: ='Hourly Bike-Ped Counts'!C334 -> 25 | E40: ='Hourly Bike-Ped Counts'!C335 -> 18 | F40: ='Hourly Bike-Ped Counts'!C336 -> 0 | G40: =SUM(C40:F40) -> 71
B41: 0.38541667 | C41: ='Hourly Bike-Ped Counts'!C342 -> 4 | D41: ='Hourly Bike-Ped Counts'!C343 -> 0 | E41: ='Hourly Bike-Ped Counts'!C344 -> 0 | F41: ='Hourly Bike-Ped Counts'!C345 -> 0 | G41: =SUM(C41:F41) -> 4
...

Sheet Charts
B14: From | V14: To
H17: Sidewalk N-W | I17: Bike Lane N-W | J17: Road N | M17: Bike Lane N-E | N17: Sidewalk N-E | AB17: Sidewalk N-W | AC17: Bike Lane N-W | AD17: Road N | AG17: Bike Lane N-E | AH17: Sidewalk N-E
H19: =H20/'Hourly Bike-Ped Counts'!$F$881 -> 0.12440191 | I19: =I20/'Hourly Bike-Ped Counts'!$F$881 -> 0.020733652 | J19: =J20/'Hourly Bike-Ped Counts'!$F$881 -> 0 | M19: =M20/'Hourly Bike-Ped Counts'!$F$881 -> 0.0079744817 | N19: =N20/'Hourly Bike-Ped Counts'!$F$881 -> 0.063795853 | AB19: =AB20/'Hourly Bike-Ped Counts'!$X$881 -> 0.1291866 | AC19: =AC20/'Hourly Bike-Ped Counts'!$X$881 -> 0.023923445 | AD19: =AD20/'Hourly Bike-Ped Counts'!$X$881 -> 0 | AG19: =AG20/'Hourly Bike-Ped Counts'!$X$881 -> 0.019138756 | AH19: =AH20/'Hourly Bike-Ped Counts'!$X$881 -> 0.089314195
H20: ='Hourly Bike-Ped Counts'!R879 -> 78 | I20: ='Hourly Bike-Ped Counts'!J879 -> 13 | J20: ='Hourly Bike-Ped Counts'!G879 -> 0 | M20: ='Hourly Bike-Ped Counts'!K879 -> 5 | N20: ='Hourly Bike-Ped Counts'!S879 -> 40 | AB20: ='Hourly Bike-Ped Counts'!AJ879 -> 81 | AC20: ='Hourly Bike-Ped Counts'!AB879 -> 15 | AD20: ='Hourly Bike-Ped Counts'!Y879 -> 0 | AG20: ='Hourly Bike-Ped Counts'!AC879 -> 12 | AH20: ='Hourly Bike-Ped Counts'!AK879 -> 56
B24: Sidewalk W-N | C24: =D24/'Hourly Bike-Ped Counts'!$F$881 -> 0.073365231 | D24: ='Hourly Bike-Ped Counts'!Q879 -> 46 | R24: ='Hourly Bike-Ped Counts'!T879 -> 37 | S24: =R24/'Hourly Bike-Ped Counts'!$F$881 -> 0.059011164 | T24: Sidewalk E-N | V24: Sidewalk W-N | W24: =X24/'Hourly Bike-Ped Counts'!$X$881 -> 0.062200957 | X24: ='Hourly Bike-Ped Counts'!AI879 -> 39 | AL24: ='Hourly Bike-Ped Counts'!AL879 -> 36 | AM24: =AL24/'Hourly Bike-Ped Counts'!$X$881 -> 0.057416268 | AN24: Sidewalk E-N
B25: Bikeway W | C25: =D25/'Hourly Bike-Ped Counts'!$F$881 -> 0.035087719 | D25: ='Hourly Bike-Ped Counts'!N879 -> 22 | R25: ='Hourly Bike-Ped Counts'!O879 -> 57 | S25: =R25/'Hourly Bike-Ped Counts'!$F$881 -> 0.090909091 | T25: Bikeway E | V25: Bikeway W | W25: =X25/'Hourly Bike-Ped Counts'!$X$881 -> 0.055821372 | X25: ='Hourly Bike-Ped Counts'!AF879 -> 35 | AL25: ='Hourly Bike-Ped Counts'!AG879 -> 63 | AM25: =AL25/'Hourly Bike-Ped Counts'!$X$881 -> 0.10047847 | AN25: Bikeway E
B27: Road W | C27: =D27/'Hourly Bike-Ped Counts'!$F$881 -> 0.004784689 | D27: ='Hourly Bike-Ped Counts'!F879 -> 3 | R27: ='Hourly Bike-Ped Counts'!H879 -> 4 | S27: =R27/'Hourly Bike-Ped Counts'!$F$881 -> 0.0063795853 | T27: Road E | V27: Road W | W27: =X27/'Hourly Bike-Ped Counts'!$X$881 -> 0.004784689 | X27: ='Hourly Bike-Ped Counts'!X879 -> 3 | AL27: ='Hourly Bike-Ped Counts'!Z879 -> 3 | AM27: =AL27/'Hourly Bike-Ped Counts'!$X$881 -> 0.004784689 | AN27: Road E
B29: Sidewalk W-S | C29: =D29/'Hourly Bike-Ped Counts'!$F$881 -> 0.028708134 | D29: ='Hourly Bike-Ped Counts'!P879 -> 18 | R29: ='Hourly Bike-Ped Counts'!U879 -> 43 | S29: =R29/'Hourly Bike-Ped Counts'!$F$881 -> 0.068580542 | T29: Trail E-S | V29: Sidewalk W-S | W29: =X29/'Hourly Bike-Ped Counts'!$X$881 -> 0.038277512 | X29: ='Hourly Bike-Ped Counts'!AH879 -> 24 | AL29: ='Hourly Bike-Ped Counts'!AM879 -> 31 | AM29: =AL29/'Hourly Bike-Ped Counts'!$X$881 -> 0.049441786 | AN29: Trail E-S
H33: ='Hourly Bike-Ped Counts'!W879 -> 236 | I33: ='Hourly Bike-Ped Counts'!M879 -> 2 | J33: ='Hourly Bike-Ped Counts'!I879 -> 0 | M33: ='Hourly Bike-Ped Counts'!L879 -> 6 | N33: ='Hourly Bike-Ped Counts'!V879 -> 17 | AB33: ='Hourly Bike-Ped Counts'!AO879 -> 195 | AC33: ='Hourly Bike-Ped Counts'!AE879 -> 8 | AD33: ='Hourly Bike-Ped Counts'!AA879 -> 0 | AG33: ='Hourly Bike-Ped Counts'!AD879 -> 0 | AH33: ='Hourly Bike-Ped Counts'!AN879 -> 26
H34: =H33/'Hourly Bike-Ped Counts'!$F$881 -> 0.37639553 | I34: =I33/'Hourly Bike-Ped Counts'!$F$881 -> 0.0031897927 | J34: =J33/'Hourly Bike-Ped Counts'!$F$881 -> 0 | M34: =M33/'Hourly Bike-Ped Counts'!$F$881 -> 0.009569378 | N34: =N33/'Hourly Bike-Ped Counts'!$F$881 -> 0.027113238 | AB34: =AB33/'Hourly Bike-Ped Counts'!$X$881 -> 0.31100478 | AC34: =AC33/'Hourly Bike-Ped Counts'!$X$881 -> 0.012759171 | AD34: =AD33/'Hourly Bike-Ped Counts'!$X$881 -> 0 | AG34: =AG33/'Hourly Bike-Ped Counts'!$X$881 -> 0 | AH34: =AH33/'Hourly Bike-Ped Counts'!$X$881 -> 0.041467305
H36: Sidewalk S-W | I36: Bike Lane S-W | J36: Road S | M36: Bike Lane S-E | N36: Sidewalk S-E | AB36: Sidewalk S-W | AC36: Bike Lane S-W | AD36: Road S | AG36: Bike Lane S-E | AH36: Sidewalk S-E
