Workbook

Sheet Hourly Bike-Ped Counts
B3: Ped Counter. 1 block for each hour. If desired, record demographic (want to see % of women + children). i.e. mid-aged woman, senior woman, elementary girl etc.
B4: gender, age, rec/commute/school
B5: In = going _____ | C5: Out = going _____
B6: Date:
G8: From | Y8: To
G9: Road | K9: Bike Lane | O9: Bikeway | Q9: Sidewalk | Y9: Road | AC9: Bike Lane | AG9: Bikeway | AI9: Sidewalk | AQ9: Car No Yield | AS9: Car in Bikeway | AT9: Student | AU9: Bike Passenger | AV9: Ped Out of Crosswalk | AW9: Stroller | AX9: Jogger
B10: 0 | C10: Intersection Count | D10: Totals | G10: W | H10: N | I10: E | J10: S | K10: N-W | L10: N-E | M10: S-E | N10: S-W | O10: W | P10: E | Q10: W-S | R10: W-N | S10: N-W | T10: N-E | U10: E-N | V10: E-S | W10: S-E | X10: S-W | Y10: W | Z10: N | AA10: E | AB10: S | AC10: N-W | AD10: N-E | AE10: S-E | AF10: S-W | AG10: W | AH10: E | AI10: W-S | AJ10: W-N | AK10: N-W | AL10: N-E | AM10: E-N | AN10: E-S | AO10: S-E | AP10: S-W
B11: Pedestrian | D11: =C11 -> 0 | F11: Pedestrian
B12: Bike | D12: =C12 -> 0 | F12: Bike
B13: Scooter | D13: =C13 -> 0 | F13: Scooter
B14: Other | D14: =C14 -> 0 | F14: Other
C15: 15-min Interval Total | D15: =SUM(D11:D14) -> 0
G17: From | Y17: To
G18: Road | K18: Bike Lane | O18: Bikeway | Q18: Sidewalk | Y18: Road | AC18: Bike Lane | AG18: Bikeway | AI18: Sidewalk | AQ18: Car No Yield | AS18: Car in Bikeway | AT18: Student | AU18: Bike Passenger | AV18: Ped Out of Crosswalk | AW18: Stroller | AX18: Jogger
B19: 0.010416667 | C19: Intersection Count | D19: Totals | G19: W | H19: N | I19: E | J19: S | K19: N-W | L19: N-E | M19: S-E | N19: S-W | O19: W | P19: E | Q19: W-S | R19: W-N | S19: N-W | T19: N-E | U19: E-N | V19: E-S | W19: S-E | X19: S-W | Y19: W | Z19: N | AA19: E | AB19: S | AC19: N-W | AD19: N-E | AE19: S-E | AF19: S-W | AG19: W | AH19: E | AI19: W-S | AJ19: W-N | AK19: N-W | AL19: N-E | AM19: E-N | AN19: E-S | AO19: S-E | AP19: S-W
B20: Pedestrian | D20: =C20 -> 0 | F20: Pedestrian
B21: Bike | D21: =C21 -> 0 | F21: Bike
B22: Scooter | D22: =C22 -> 0 | F22: Scooter
B23: Other | D23: =C23 -> 0 | F23: Other
C24: 15-min Interval Total | D24: =SUM(D20:D23) -> 0
G26: From | Y26: To
G27: Road | K27: Bike Lane | O27: Bikeway | Q27: Sidewalk | Y27: Road | AC27: Bike Lane | AG27: Bikeway | AI27: Sidewalk | AQ27: Car No Yield | AS27: Car in Bikeway | AT27: Student | AU27: Bike Passenger | AV27: Ped Out of Crosswalk | AW27: Stroller | AX27: Jogger
B28: 0.020833333 | C28: Intersection Count | D28: Totals | G28: W | H28: N | I28: E | J28: S | K28: N-W | L28: N-E | M28: S-E | N28: S-W | O28: W | P28: E | Q28: W-S | R28: W-N | S28: N-W | T28: N-E | U28: E-N | V28: E-S | W28: S-E | X28: S-W | Y28: W | Z28: N | AA28: E | AB28: S | AC28: N-W | AD28: N-E | AE28: S-E | AF28: S-W | AG28: W | AH28: E | AI28: W-S | AJ28: W-N | AK28: N-W | AL28: N-E | AM28: E-N | AN28: E-S | AO28: S-E | AP28: S-W
B29: Pedestrian | D29: =C29 -> 0 | F29: Pedestrian
B30: Bike | D30: =C30 -> 0 | F30: Bike
B31: Scooter | D31: =C31 -> 0 | F31: Scooter
B32: Other | D32: =C32 -> 0 | F32: Other
C33: 15-min Interval Total | D33: =SUM(D29:D32) -> 0
G35: From | Y35: To
G36: Road | K36: Bike Lane | O36: Bikeway | Q36: Sidewalk | Y36: Road | AC36: Bike Lane | AG36: Bikeway | AI36: Sidewalk | AQ36: Car No Yield | AS36: Car in Bikeway | AT36: Student | AU36: Bike Passenger | AV36: Ped Out of Crosswalk | AW36: Stroller | AX36: Jogger
B37: 0.03125 | C37: Intersection Count | D37: Totals | G37: W | H37: N | I37: E | J37: S | K37: N-W | L37: N-E | M37: S-E | N37: S-W | O37: W | P37: E | Q37: W-S | R37: W-N | S37: N-W | T37: N-E | U37: E-N | V37: E-S | W37: S-E | X37: S-W | Y37: W | Z37: N | AA37: E | AB37: S | AC37: N-W | AD37: N-E | AE37: S-E | AF37: S-W | AG37: W | AH37: E | AI37: W-S | AJ37: W-N | AK37: N-W | AL37: N-E | AM37: E-N | AN37: E-S | AO37: S-E | AP37: S-W
B38: Pedestrian | D38: =C38 -> 0 | F38: Pedestrian
B39: Bike | D39: =C39 -> 0 | F39: Bike
B40: Scooter | D40: =C40 -> 0 | F40: Scooter
B41: Other | D41: =C41 -> 0 | F41: Other
C42: 15-min Interval Total | D42: =SUM(D38:D41) -> 0
G44: From | Y44: To
G45: Road | K45: Bike Lane | O45: Bikeway | Q45: Sidewalk | Y45: Road | AC45: Bike Lane | AG45: Bikeway | AI45: Sidewalk | AQ45: Car No Yield | AS45: Car in Bikeway | AT45: Student | AU45: Bike Passenger | AV45: Ped Out of Crosswalk | AW45: Stroller | AX45: Jogger
B46: 0.041666667 | C46: Intersection Count | D46: Totals | G46: W | H46: N | I46: E | J46: S | K46: N-W | L46: N-E | M46: S-E | N46: S-W | O46: W | P46: E | Q46: W-S | R46: W-N | S46: N-W | T46: N-E | U46: E-N | V46: E-S | W46: S-E | X46: S-W | Y46: W | Z46: N | AA46: E | AB46: S | AC46: N-W | AD46: N-E | AE46: S-E | AF46: S-W | AG46: W | AH46: E | AI46: W-S | AJ46: W-N | AK46: N-W | AL46: N-E | AM46: E-N | AN46: E-S | AO46: S-E | AP46: S-W
B47: Pedestrian | D47: =C47 -> 0 | F47: Pedestrian
...

Sheet Count Summary
B2: 15-Minute Intervals | I2: 1-Hour Intervals
B3: Time | C3: Pedestrian | D3: Bike | E3: Scooter | F3: Other | G3: 15-min Total | I3: Time | J3: Pedestrian | K3: Bike | L3: Scooter | M3: Other | N3: Hourly Total
B4: 0 | C4: ='Hourly Bike-Ped Counts'!D11 -> 0 | D4: ='Hourly Bike-Ped Counts'!D12 -> 0 | E4: ='Hourly Bike-Ped Counts'!D13 -> 0 | F4: ='Hourly Bike-Ped Counts'!D14 -> 0 | G4: =SUM(C4:F4) -> 0 | I4: 0 | J4: =SUM(C4:C7) -> 0 | K4: =SUM(D4:D7) -> 0 | L4: =SUM(E4:E7) -> 0 | M4: =SUM(F4:F7) -> 0 | N4: =SUM(J4:M4) -> 0
B5: 0.010416667 | C5: ='Hourly Bike-Ped Counts'!D20 -> 0 | D5: ='Hourly Bike-Ped Counts'!D21 -> 0 | E5: ='Hourly Bike-Ped Counts'!D22 -> 0 | F5: ='Hourly Bike-Ped Counts'!D23 -> 0 | G5: =SUM(C5:F5) -> 0 | I5: 0.041666667 | J5: =SUM(C8:C11) -> 0 | K5: =SUM(D8:D11) -> 0 | L5: =SUM(E8:E11) -> 0 | M5: =SUM(F8:F11) -> 0 | N5: =SUM(J5:M5) -> 0
B6: 0.020833333 | C6: ='Hourly Bike-Ped Counts'!D29 -> 0 | D6: ='Hourly Bike-Ped Counts'!D30 -> 0 | E6: ='Hourly Bike-Ped Counts'!D31 -> 0 | F6: ='Hourly Bike-Ped Counts'!D32 -> 0 | G6: =SUM(C6:F6) -> 0 | I6: 0.083333333 | J6: =SUM(C12:C15) -> 0 | K6: =SUM(D12:D15) -> 0 | L6: =SUM(E12:E15) -> 0 | M6: =SUM(F12:F15) -> 0 | N6: =SUM(J6:M6) -> 0
B7: 0.03125 | C7: ='Hourly Bike-Ped Counts'!D38 -> 0 | D7: ='Hourly Bike-Ped Counts'!D39 -> 0 | E7: ='Hourly Bike-Ped Counts'!D40 -> 0 | F7: ='Hourly Bike-Ped Counts'!D42 -> 0 | G7: =SUM(C7:F7) -> 0 | I7: 0.125 | J7: =SUM(C16:C19) -> 0 | K7: =SUM(D16:D19) -> 0 | L7: =SUM(E16:E19) -> 0 | M7: =SUM(F16:F19) -> 0 | N7: =SUM(J7:M7) -> 0
B8: 0.041666667 | C8: ='Hourly Bike-Ped Counts'!D47 -> 0 | D8: ='Hourly Bike-Ped Counts'!D48 -> 0 | E8: ='Hourly Bike-Ped Counts'!D49 -> 0 | F8: ='Hourly Bike-Ped Counts'!D50 -> 0 | G8: =SUM(C8:F8) -> 0 | I8: 0.16666667 | J8: =SUM(C20:C23) -> 0 | K8: =SUM(D20:D23) -> 0 | L8: =SUM(E20:E23) -> 0 | M8: =SUM(F20:F23) -> 0 | N8: =SUM(J8:M8) -> 0
B9: 0.052083333 | C9: ='Hourly Bike-Ped Counts'!D56 -> 0 | D9: ='Hourly Bike-Ped Counts'!D57 -> 0 | E9: ='Hourly Bike-Ped Counts'!D58 -> 0 | F9: ='Hourly Bike-Ped Counts'!D59 -> 0 | G9: =SUM(C9:F9) -> 0 | I9: 0.20833333 | J9: =SUM(C24:C27) -> 2 | K9: =SUM(D24:D27) -> 1 | L9: =SUM(E24:E27) -> 0 | M9: =SUM(F24:F27) -> 0 | N9: =SUM(J9:M9) -> 3
B10: 0.0625 | C10: ='Hourly Bike-Ped Counts'!D565 -> 0 | D10: ='Hourly Bike-Ped Counts'!D66 -> 0 | E10: ='Hourly Bike-Ped Counts'!D67 -> 0 | F10: ='Hourly Bike-Ped Counts'!D68 -> 0 | G10: =SUM(C10:F10) -> 0 | I10: 0.25 | J10: =SUM(C28:C31) -> 36 | K10: =SUM(D28:D31) -> 0 | L10: =SUM(E28:E31) -> 0 | M10: =SUM(F28:F31) -> 0 | N10: =SUM(J10:M10) -> 36
B11: 0.072916667 | C11: ='Hourly Bike-Ped Counts'!D74 -> 0 | D11: ='Hourly Bike-Ped Counts'!D75 -> 0 | E11: ='Hourly Bike-Ped Counts'!D76 -> 0 | F11: ='Hourly Bike-Ped Counts'!D77 -> 0 | G11: =SUM(C11:F11) -> 0 | I11: 0.29166667 | J11: =SUM(C32:C35) -> 19 | K11: =SUM(D32:D35) -> 9 | L11: =SUM(E32:E35) -> 1 | M11: =SUM(F32:F35) -> 0 | N11: =SUM(J11:M11) -> 29
B12: 0.083333333 | C12: ='Hourly Bike-Ped Counts'!D83 -> 0 | D12: ='Hourly Bike-Ped Counts'!D84 -> 0 | E12: ='Hourly Bike-Ped Counts'!D85 -> 0 | F12: ='Hourly Bike-Ped Counts'!D86 -> 0 | G12: =SUM(C12:F12) -> 0 | I12: 0.33333333 | J12: =SUM(C36:C39) -> 75 | K12: =SUM(D36:D39) -> 70 | L12: =SUM(E36:E39) -> 37 | M12: =SUM(F36:F39) -> 0 | N12: =SUM(J12:M12) -> 182
B13: 0.09375 | C13: ='Hourly Bike-Ped Counts'!D92 -> 0 | D13: ='Hourly Bike-Ped Counts'!D93 -> 0 | E13: ='Hourly Bike-Ped Counts'!D94 -> 0 | F13: ='Hourly Bike-Ped Counts'!D95 -> 0 | G13: =SUM(C13:F13) -> 0 | I13: 0.375 | J13: =SUM(C40:C43) -> 82 | K13: =SUM(D40:D43) -> 35 | L13: =SUM(E40:E43) -> 19 | M13: =SUM(F40:F43) -> 1 | N13: =SUM(J13:M13) -> 137
B14: 0.10416667 | C14: ='Hourly Bike-Ped Counts'!D101 -> 0 | D14: ='Hourly Bike-Ped Counts'!D102 -> 0 | E14: ='Hourly Bike-Ped Counts'!D103 -> 0 | F14: ='Hourly Bike-Ped Counts'!D104 -> 0 | G14: =SUM(C14:F14) -> 0 | I14: 0.41666667 | J14: =SUM(C44:C47) -> 4 | K14: =SUM(D44:D47) -> 6 | L14: =SUM(E44:E47) -> 0 | M14: =SUM(F44:F47) -> 0 | N14: =SUM(J14:M14) -> 10
B15: 0.11458333 | C15: ='Hourly Bike-Ped Counts'!D110 -> 0 | D15: ='Hourly Bike-Ped Counts'!D111 -> 0 | E15: ='Hourly Bike-Ped Counts'!D112 -> 0 | F15: ='Hourly Bike-Ped Counts'!D113 -> 0 | G15: =SUM(C15:F15) -> 0 | I15: 0.45833333 | J15: =SUM(C48:C51) -> 6 | K15: =SUM(D48:D51) -> 9 | L15: =SUM(E48:E51) -> 0 | M15: =SUM(F48:F51) -> 0 | N15: =SUM(J15:M15) -> 15
B16: 0.125 | C16: ='Hourly Bike-Ped Counts'!D119 -> 0 | D16: ='Hourly Bike-Ped Counts'!D120 -> 0 | E16: ='Hourly Bike-Ped Counts'!D121 -> 0 | F16: ='Hourly Bike-Ped Counts'!D122 -> 0 | G16: =SUM(C16:F16) -> 0 | I16: 0.5 | J16: =SUM(C52:C55) -> 6 | K16: =SUM(D52:D55) -> 3 | L16: =SUM(E52:E55) -> 0 | M16: =SUM(F52:F55) -> 0 | N16: =SUM(J16:M16) -> 9
B17: 0.13541667 | C17: ='Hourly Bike-Ped Counts'!D128 -> 0 | D17: ='Hourly Bike-Ped Counts'!D129 -> 0 | E17: ='Hourly Bike-Ped Counts'!D130 -> 0 | F17: ='Hourly Bike-Ped Counts'!D131 -> 0 | G17: =SUM(C17:F17) -> 0 | I17: 0.54166667 | J17: =SUM(C56:C59) -> 4 | K17: =SUM(D56:D59) -> 0 | L17: =SUM(E56:E59) -> 0 | M17: =SUM(F56:F59) -> 0 | N17: =SUM(J17:M17) -> 4
B18: 0.14583333 | C18: ='Hourly Bike-Ped Counts'!D137 -> 0 | D18: ='Hourly Bike-Ped Counts'!D138 -> 0 | E18: ='Hourly Bike-Ped Counts'!D139 -> 0 | F18: ='Hourly Bike-Ped Counts'!D140 -> 0 | G18: =SUM(C18:F18) -> 0 | I18: 0.58333333 | J18: =SUM(C60:C63) -> 7 | K18: =SUM(D60:D63) -> 2 | L18: =SUM(E60:E63) -> 0 | M18: =SUM(F60:F63) -> 0 | N18: =SUM(J18:M18) -> 9
B19: 0.15625 | C19: ='Hourly Bike-Ped Counts'!D146 -> 0 | D19: ='Hourly Bike-Ped Counts'!D147 -> 0 | E19: ='Hourly Bike-Ped Counts'!D148 -> 0 | F19: ='Hourly Bike-Ped Counts'!D149 -> 0 | G19: =SUM(C19:F19) -> 0 | I19: 0.625 | J19: =SUM(C64:C67) -> 122 | K19: =SUM(D64:D67) -> 108 | L19: =SUM(E64:E67) -> 42 | M19: =SUM(F64:F67) -> 1 | N19: =SUM(J19:M19) -> 273
B20: 0.16666667 | C20: ='Hourly Bike-Ped Counts'!D155 -> 0 | D20: ='Hourly Bike-Ped Counts'!D156 -> 0 | E20: ='Hourly Bike-Ped Counts'!D157 -> 0 | F20: ='Hourly Bike-Ped Counts'!D158 -> 0 | G20: =SUM(C20:F20) -> 0 | I20: 0.66666667 | J20: =SUM(C68:C71) -> 6 | K20: =SUM(D68:D71) -> 4 | L20: =SUM(E68:E71) -> 5 | M20: =SUM(F68:F71) -> 0 | N20: =SUM(J20:M20) -> 15
B21: 0.17708333 | C21: ='Hourly Bike-Ped Counts'!D164 -> 0 | D21: ='Hourly Bike-Ped Counts'!D165 -> 0 | E21: ='Hourly Bike-Ped Counts'!D166 -> 0 | F21: ='Hourly Bike-Ped Counts'!D167 -> 0 | G21: =SUM(C21:F21) -> 0 | I21: 0.70833333 | J21: =SUM(C72:C75) -> 5 | K21: =SUM(D72:D75) -> 4 | L21: =SUM(E72:E75) -> 1 | M21: =SUM(F72:F75) -> 0 | N21: =SUM(J21:M21) -> 10
B22: 0.1875 | C22: ='Hourly Bike-Ped Counts'!D173 -> 0 | D22: ='Hourly Bike-Ped Counts'!D174 -> 0 | E22: ='Hourly Bike-Ped Counts'!D175 -> 0 | F22: ='Hourly Bike-Ped Counts'!D176 -> 0 | G22: =SUM(C22:F22) -> 0 | I22: 0.75 | J22: =SUM(C76:C79) -> 0 | K22: =SUM(D76:D79) -> 5 | L22: =SUM(E76:E79) -> 3 | M22: =SUM(F76:F79) -> 0 | N22: =SUM(J22:M22) -> 8
B23: 0.19791667 | C23: ='Hourly Bike-Ped Counts'!D182 -> 0 | D23: ='Hourly Bike-Ped Counts'!D183 -> 0 | E23: ='Hourly Bike-Ped Counts'!D184 -> 0 | F23: ='Hourly Bike-Ped Counts'!D185 -> 0 | G23: =SUM(C23:F23) -> 0 | I23: 0.79166667 | J23: =SUM(C80:C83) -> 15 | K23: =SUM(D80:D83) -> 6 | L23: =SUM(E80:E83) -> 0 | M23: =SUM(F80:F83) -> 0 | N23: =SUM(J23:M23) -> 21
B24: 0.20833333 | C24: ='Hourly Bike-Ped Counts'!D191 -> 0 | D24: ='Hourly Bike-Ped Counts'!D192 -> 0 | E24: ='Hourly Bike-Ped Counts'!D193 -> 0 | F24: ='Hourly Bike-Ped Counts'!D194 -> 0 | G24: =SUM(C24:F24) -> 0 | I24: 0.83333333 | J24: =SUM(C84:C87) -> 21 | K24: =SUM(D84:D87) -> 8 | L24: =SUM(E84:E87) -> 0 | M24: =SUM(F84:F87) -> 0 | N24: =SUM(J24:M24) -> 29
B25: 0.21875 | C25: ='Hourly Bike-Ped Counts'!D200 -> 0 | D25: ='Hourly Bike-Ped Counts'!D201 -> 0 | E25: ='Hourly Bike-Ped Counts'!D202 -> 0 | F25: ='Hourly Bike-Ped Counts'!D203 -> 0 | G25: =SUM(C25:F25) -> 0 | I25: 0.875 | J25: =SUM(C88:C91) -> 6 | K25: =SUM(D88:D91) -> 2 | L25: =SUM(E88:E91) -> 0 | M25: =SUM(F88:F91) -> 0 | N25: =SUM(J25:M25) -> 8
B26: 0.22916667 | C26: ='Hourly Bike-Ped Counts'!D209 -> 0 | D26: ='Hourly Bike-Ped Counts'!D210 -> 0 | E26: ='Hourly Bike-Ped Counts'!D211 -> 0 | F26: ='Hourly Bike-Ped Counts'!D212 -> 0 | G26: =SUM(C26:F26) -> 0 | I26: 0.91666667 | J26: =SUM(C92:C95) -> 2 | K26: =SUM(D92:D95) -> 0 | L26: =SUM(E92:E95) -> 0 | M26: =SUM(F92:F95) -> 0 | N26: =SUM(J26:M26) -> 2
B27: 0.23958333 | C27: ='Hourly Bike-Ped Counts'!D218 -> 2 | D27: ='Hourly Bike-Ped Counts'!D219 -> 1 | E27: ='Hourly Bike-Ped Counts'!D220 -> 0 | F27: ='Hourly Bike-Ped Counts'!D221 -> 0 | G27: =SUM(C27:F27) -> 3 | I27: 0.95833333 | J27: =SUM(C96:C99) -> 1 | K27: =SUM(D96:D99) -> 0 | L27: =SUM(E96:E99) -> 0 | M27: =SUM(F96:F99) -> 0 | N27: =SUM(J27:M27) -> 1
B28: 0.25 | C28: ='Hourly Bike-Ped Counts'!D227 -> 4 | D28: ='Hourly Bike-Ped Counts'!D228 -> 0 | E28: ='Hourly Bike-Ped Counts'!D229 -> 0 | F28: ='Hourly Bike-Ped Counts'!D230 -> 0 | G28: =SUM(C28:F28) -> 4 | I28: Total | J28: =SUM(J4:J27) -> 419 | K28: =SUM(K4:K27) -> 272 | L28: =SUM(L4:L27) -> 108 | M28: =SUM(M4:M27) -> 2 | N28: =SUM(N4:N27) -> 801
B29: 0.26041667 | C29: ='Hourly Bike-Ped Counts'!D236 -> 12 | D29: ='Hourly Bike-Ped Counts'!D237 -> 0 | E29: ='Hourly Bike-Ped Counts'!D238 -> 0 | F29: ='Hourly Bike-Ped Counts'!D239 -> 0 | G29: =SUM(C29:F29) -> 12
B30: 0.27083333 | C30: ='Hourly Bike-Ped Counts'!D245 -> 8 | D30: ='Hourly Bike-Ped Counts'!D246 -> 0 | E30: ='Hourly Bike-Ped Counts'!D247 -> 0 | F30: ='Hourly Bike-Ped Counts'!D248 -> 0 | G30: =SUM(C30:F30) -> 8
B31: 0.28125 | C31: ='Hourly Bike-Ped Counts'!D254 -> 12 | D31: ='Hourly Bike-Ped Counts'!D255 -> 0 | E31: ='Hourly Bike-Ped Counts'!D256 -> 0 | F31: ='Hourly Bike-Ped Counts'!D257 -> 0 | G31: =SUM(C31:F31) -> 12
B32: 0.29166667 | C32: ='Hourly Bike-Ped Counts'!D263 -> 6 | D32: ='Hourly Bike-Ped Counts'!D264 -> 2 | E32: ='Hourly Bike-Ped Counts'!D265 -> 1 | F32: ='Hourly Bike-Ped Counts'!D266 -> 0 | G32: =SUM(C32:F32) -> 9
B33: 0.30208333 | C33: ='Hourly Bike-Ped Counts'!D272 -> 5 | D33: ='Hourly Bike-Ped Counts'!D273 -> 3 | E33: ='Hourly Bike-Ped Counts'!D274 -> 0 | F33: ='Hourly Bike-Ped Counts'!D275 -> 0 | G33: =SUM(C33:F33) -> 8
B34: 0.3125 | C34: ='Hourly Bike-Ped Counts'!D281 -> 3 | D34: ='Hourly Bike-Ped Counts'!D282 -> 1 | E34: ='Hourly Bike-Ped Counts'!D283 -> 0 | F34: ='Hourly Bike-Ped Counts'!D284 -> 0 | G34: =SUM(C34:F34) -> 4
B35: 0.32291667 | C35: ='Hourly Bike-Ped Counts'!D290 -> 5 | D35: ='Hourly Bike-Ped Counts'!D291 -> 3 | E35: ='Hourly Bike-Ped Counts'!D292 -> 0 | F35: ='Hourly Bike-Ped Counts'!D293 -> 0 | G35: =SUM(C35:F35) -> 8
B36: 0.33333333 | C36: ='Hourly Bike-Ped Counts'!D299 -> 4 | D36: ='Hourly Bike-Ped Counts'!D300 -> 2 | E36: ='Hourly Bike-Ped Counts'!D301 -> 0 | F36: ='Hourly Bike-Ped Counts'!D302 -> 0 | G36: =SUM(C36:F36) -> 6
B37: 0.34375 | C37: ='Hourly Bike-Ped Counts'!D308 -> 5 | D37: ='Hourly Bike-Ped Counts'!D309 -> 2 | E37: ='Hourly Bike-Ped Counts'!D310 -> 0 | F37: ='Hourly Bike-Ped Counts'!D311 -> 0 | G37: =SUM(C37:F37) -> 7
B38: 0.35416667 | C38: ='Hourly Bike-Ped Counts'!D317 -> 9 | D38: ='Hourly Bike-Ped Counts'!D318 -> 6 | E38: ='Hourly Bike-Ped Counts'!D319 -> 2 | F38: ='Hourly Bike-Ped Counts'!D320 -> 0 | G38: =SUM(C38:F38) -> 17
B39: 0.36458333 | C39: ='Hourly Bike-Ped Counts'!D326 -> 57 | D39: ='Hourly Bike-Ped Counts'!D327 -> 60 | E39: ='Hourly Bike-Ped Counts'!D328 -> 35 | F39: ='Hourly Bike-Ped Counts'!D329 -> 0 | G39: =SUM(C39:F39) -> 152
B40: 0.375 | C40: ='Hourly Bike-Ped Counts'!D335 -> 41 | D40: ='Hourly Bike-Ped Counts'!D336 -> 23 | E40: ='Hourly Bike-Ped Counts'!D337 -> 17 | F40: ='Hourly Bike-Ped Counts'!D338 -> 1 | G40: =SUM(C40:F40) -> 82
B41: 0.38541667 | C41: ='Hourly Bike-Ped Counts'!D344 -> 34 | D41: ='Hourly Bike-Ped Counts'!D345 -> 12 | E41: ='Hourly Bike-Ped Counts'!D346 -> 2 | F41: ='Hourly Bike-Ped Counts'!D347 -> 0 | G41: =SUM(C41:F41) -> 48
...

Sheet Charts
B14: From | V14: To
H17: Sidewalk N-W | I17: Bike Lane N-W | J17: Road N | M17: Bike Lane N-E | N17: Sidewalk N-E | AB17: Sidewalk N-W | AC17: Bike Lane N-W | AD17: Road N | AG17: Bike Lane N-E | AH17: Sidewalk N-E
H19: =H20/'Hourly Bike-Ped Counts'!$G$883 -> 0.11985019 | I19: =I20/'Hourly Bike-Ped Counts'!$G$883 -> 0.016229713 | J19: =J20/'Hourly Bike-Ped Counts'!$G$883 -> 0.0012484395 | M19: =M20/'Hourly Bike-Ped Counts'!$G$883 -> 0 | N19: =N20/'Hourly Bike-Ped Counts'!$G$883 -> 0.072409488 | AB19: =AB20/'Hourly Bike-Ped Counts'!$Y$883 -> 0.14481898 | AC19: =AC20/'Hourly Bike-Ped Counts'!$Y$883 -> 0.0087390762 | AD19: =AD20/'Hourly Bike-Ped Counts'!$Y$883 -> 0.0012484395 | AG19: =AG20/'Hourly Bike-Ped Counts'!$Y$883 -> 0.0099875156 | AH19: =AH20/'Hourly Bike-Ped Counts'!$Y$883 -> 0.081148564
H20: ='Hourly Bike-Ped Counts'!S881 -> 96 | I20: ='Hourly Bike-Ped Counts'!K881 -> 13 | J20: ='Hourly Bike-Ped Counts'!H881 -> 1 | M20: ='Hourly Bike-Ped Counts'!L881 -> 0 | N20: ='Hourly Bike-Ped Counts'!T881 -> 58 | AB20: ='Hourly Bike-Ped Counts'!AK881 -> 116 | AC20: ='Hourly Bike-Ped Counts'!AC881 -> 7 | AD20: ='Hourly Bike-Ped Counts'!Z881 -> 1 | AG20: ='Hourly Bike-Ped Counts'!AD881 -> 8 | AH20: ='Hourly Bike-Ped Counts'!AL881 -> 65
B24: Sidewalk W-N | C24: =D24/'Hourly Bike-Ped Counts'!$G$883 -> 0.057428215 | D24: ='Hourly Bike-Ped Counts'!R881 -> 46 | R24: ='Hourly Bike-Ped Counts'!U881 -> 52 | S24: =R24/'Hourly Bike-Ped Counts'!$G$883 -> 0.064918851 | T24: Sidewalk E-N | V24: Sidewalk W-N | W24: =X24/'Hourly Bike-Ped Counts'!$Y$883 -> 0.064918851 | X24: ='Hourly Bike-Ped Counts'!AJ881 -> 52 | AL24: ='Hourly Bike-Ped Counts'!AM881 -> 44 | AM24: =AL24/'Hourly Bike-Ped Counts'!$Y$883 -> 0.054931336 | AN24: Sidewalk E-N
B25: Bikeway W | C25: =D25/'Hourly Bike-Ped Counts'!$G$883 -> 0.063670412 | D25: ='Hourly Bike-Ped Counts'!O881 -> 51 | R25: ='Hourly Bike-Ped Counts'!P881 -> 86 | S25: =R25/'Hourly Bike-Ped Counts'!$G$883 -> 0.10736579 | T25: Bikeway E | V25: Bikeway W | W25: =X25/'Hourly Bike-Ped Counts'!$Y$883 -> 0.072409488 | X25: ='Hourly Bike-Ped Counts'!AG881 -> 58 | AL25: ='Hourly Bike-Ped Counts'!AH881 -> 76 | AM25: =AL25/'Hourly Bike-Ped Counts'!$Y$883 -> 0.094881398 | AN25: Bikeway E
B27: Road W | C27: =D27/'Hourly Bike-Ped Counts'!$G$883 -> 0.0062421973 | D27: ='Hourly Bike-Ped Counts'!G881 -> 5 | R27: ='Hourly Bike-Ped Counts'!I881 -> 6 | S27: =R27/'Hourly Bike-Ped Counts'!$G$883 -> 0.0074906367 | T27: Road E | V27: Road W | W27: =X27/'Hourly Bike-Ped Counts'!$Y$883 -> 0.0087390762 | X27: ='Hourly Bike-Ped Counts'!Y881 -> 7 | AL27: ='Hourly Bike-Ped Counts'!AA881 -> 4 | AM27: =AL27/'Hourly Bike-Ped Counts'!$Y$883 -> 0.0049937578 | AN27: Road E
B29: Sidewalk W-S | C29: =D29/'Hourly Bike-Ped Counts'!$G$883 -> 0.042446941 | D29: ='Hourly Bike-Ped Counts'!Q881 -> 34 | R29: ='Hourly Bike-Ped Counts'!V881 -> 55 | S29: =R29/'Hourly Bike-Ped Counts'!$G$883 -> 0.06866417 | T29: Trail E-S | V29: Sidewalk W-S | W29: =X29/'Hourly Bike-Ped Counts'!$Y$883 -> 0.032459426 | X29: ='Hourly Bike-Ped Counts'!AI881 -> 26 | AL29: ='Hourly Bike-Ped Counts'!AN881 -> 37 | AM29: =AL29/'Hourly Bike-Ped Counts'!$Y$883 -> 0.04619226 | AN29: Trail E-S
H33: ='Hourly Bike-Ped Counts'!X881 -> 252 | I33: ='Hourly Bike-Ped Counts'!N881 -> 1 | J33: ='Hourly Bike-Ped Counts'!J881 -> 1 | M33: ='Hourly Bike-Ped Counts'!M881 -> 7 | N33: ='Hourly Bike-Ped Counts'!W881 -> 37 | AB33: ='Hourly Bike-Ped Counts'!AP881 -> 252 | AC33: ='Hourly Bike-Ped Counts'!AF881 -> 4 | AD33: ='Hourly Bike-Ped Counts'!AB881 -> 0 | AG33: ='Hourly Bike-Ped Counts'!AE881 -> 0 | AH33: ='Hourly Bike-Ped Counts'!AO881 -> 44
H34: =H33/'Hourly Bike-Ped Counts'!$G$883 -> 0.31460674 | I34: =I33/'Hourly Bike-Ped Counts'!$G$883 -> 0.0012484395 | J34: =J33/'Hourly Bike-Ped Counts'!$G$883 -> 0.0012484395 | M34: =M33/'Hourly Bike-Ped Counts'!$G$883 -> 0.0087390762 | N34: =N33/'Hourly Bike-Ped Counts'!$G$883 -> 0.04619226 | AB34: =AB33/'Hourly Bike-Ped Counts'!$Y$883 -> 0.31460674 | AC34: =AC33/'Hourly Bike-Ped Counts'!$Y$883 -> 0.0049937578 | AD34: =AD33/'Hourly Bike-Ped Counts'!$Y$883 -> 0 | AG34: =AG33/'Hourly Bike-Ped Counts'!$Y$883 -> 0 | AH34: =AH33/'Hourly Bike-Ped Counts'!$Y$883 -> 0.054931336
H36: Sidewalk S-W | I36: Bike Lane S-W | J36: Road S | M36: Bike Lane S-E | N36: Sidewalk S-E | AB36: Sidewalk S-W | AC36: Bike Lane S-W | AD36: Road S | AG36: Bike Lane S-E | AH36: Sidewalk S-E
